



==================================================================================
||	Author     :  SS Kim & Adhikari Krish					||
||	Teammates  :  pk,okg							||
||	Copyright  :  Copyright 2020 						||
||	Credits    :  THER................. 					||
||	License    :  GNU 							||
||	Version    :  1.00 							||
||	Maintainer :  Adhikari Krish 						||
||	Email      :  *********@gmail.com 					||
||	Status     :  Ortholog Detection 					||
==================================================================================
==================================================================================
||	****Default Variables(Values)****					||
||	Blastp                 = blastp						||
||	Blastp_data            = ./blastp_data/					||
||	blstp_matrix           = BLOSUM45					||
||	cpu_count              = 8						||
||	genomes                = ['AAE', 'CAC', 'ECO', 'ECU', 'HIN']						||
||	infinite_loop          = 60						||
||	inflation_factor       = 1.4						||
||	mode                   = ['1', '3']						||
||	Cluster_out            = ./cluster_out					||
||	threshold_score        = 5						||
||	save_raw_blastp_score  = False						||
||	Score_file             = ./score_file/					||
||	Species                = ./species/					||
||	verbose                = False						||
==================================================================================


Ortholog Detection Program Starts Now

1. AAE
2. CAC
3. ECO
4. ECU
5. HIN
6. LLA
7. Log
8. SCE
9. SPO
10. SPY
11. SYN
12. TMA
13. YPE
14. chicken.faa
15. chimpanzee.faa
16. dog.faa
17. elegans.faa
18. fruitfly.faa
19. human.faa
20. mouse.faa
21. opossum.faa
22. pufferfish.faa
23. rat.faa
24. seasquirt.faa
25. zebrafish.faa
3 mode clustering is selected
Enter the inflation factor to cluster: Traceback (most recent call last):
  File "owPReMark.py", line 1104, in <module>
    inflation_factor = input("Enter the inflation factor to cluster: ") #
OSError: [Errno 9] Bad file descriptor
Error in sys.excepthook:
Traceback (most recent call last):
  File "/usr/lib/python3/dist-packages/apport_python_hook.py", line 63, in apport_excepthook
    from apport.fileutils import likely_packaged, get_recent_crashes
  File "/usr/lib/python3/dist-packages/apport/__init__.py", line 5, in <module>
    from apport.report import Report
  File "/usr/lib/python3/dist-packages/apport/report.py", line 30, in <module>
    import apport.fileutils
  File "/usr/lib/python3/dist-packages/apport/fileutils.py", line 23, in <module>
    from apport.packaging_impl import impl as packaging
  File "/usr/lib/python3/dist-packages/apport/packaging_impl.py", line 24, in <module>
    import apt
  File "/usr/lib/python3/dist-packages/apt/__init__.py", line 23, in <module>
    import apt_pkg
ModuleNotFoundError: No module named 'apt_pkg'

Original exception was:
Traceback (most recent call last):
  File "owPReMark.py", line 1104, in <module>
    inflation_factor = input("Enter the inflation factor to cluster: ") #
OSError: [Errno 9] Bad file descriptor
all tasks Completed
